Workbook

Sheet 汇总

Sheet 单品13GD31
A1: sku:100048028229 | D1: 销售出库 | V1: 流量 | AT1: 转化 | BH1: 京仓现货率 | BI1: 关键词排名 | BQ1: 流失分析 | CF1: 负同比每日分析
A2: 日期 | B2: 价格政策 | D2: 销售额 | L2: 模块销售占比 | V2: PV | X2: UV | Z2: 人均浏览量 | AB2: 平均停留时间 | AD2: 关注人数 | AF2: 加购人数 | AH2: 站内免费 | AJ2: 站内付费 | AL2: 站外免费 | AN2: 站外付费 | AP2: 搜索 | AR2: 内容 | AT2: 店铺转化率 | AV2: 询单 数 | AX2: 询单 率 | AZ2: 询单 成交数 | BB2: 询单 转化 | BD2: 静默成交数 | BF2: 静默转化 | BI2: 燃气热水器 | BM2: 热水器 | BQ2: 流量流失 | BV2: 销售流失
B3: Y-23 | C3: Y-22 | D3: Y-23 数量 | E3: Y-23 金额 | F3: 实际销售 | G3: Y-22 金额 | H3: 同比 | I3: 目标 | J3: 达成率 | K3: 类目占比 | L3: 推广成交金额 | M3: 同比 | N3: 占比 | O3: 客服成交金额 | P3: 同比 | Q3: 占比 | R3: Y-23 | S3: Y-22 | T3: 同比 | U3: 占比 | V3: Y-23 | W3: Y-22 | X3: Y-23 | Y3: Y-22 | Z3: Y-23 | AA3: Y-22 | AB3: Y-23 | AC3: Y-22 | AD3: Y-23 | AE3: Y-22 | AF3: Y-23 | AG3: Y-22 | AH3: Y-23 | AI3: Y-22 | AJ3: Y-23 | AK3: Y-22 | AL3: Y-23 | AM3: Y-22 | AN3: Y-23 | AO3: Y-22 | AP3: Y-23 | AQ3: Y-22 | AR3: Y-23 | AS3: Y-22 | AT3: Y-23 | AU3: Y-22 | AV3: Y-23 | AW3: Y-22 | AX3: Y-23 | AY3: Y-22 | AZ3: Y-23 | BA3: Y-22 | BB3: Y-23 | BC3: Y-22 | BD3: Y-23 | BE3: Y-22 | BF3: Y-23 | BG3: Y-22 | BI3: 层级 | BJ3: 排名 | BK3: 搜索曝光 | BL3: Y-22搜索曝光 | BM3: 层级 | BN3: 排名 | BO3: 搜索曝光 | BP3: Y-22搜索曝光 | BQ3: TOP 1 | BR3: TOP 2 | BS3: TOP 3 | BT3: TOP 4 | BU3: TOP 5 | BV3: TOP 1 | BW3: TOP 2 | BX3: TOP 3 | BY3: TOP 4 | BZ3: TOP 5 | CA3: TOP 6 | CB3: TOP 7 | CC3: TOP 8 | CD3: TOP 9 | CE3: TOP 10
A4: 填写人员 | B4: 运营 | C4: 运营 | D4: 张超 | E4: 张超 | F4: 运营 | G4: 张超 | H4: 张超 | I4: 张超 | J4: 张超 | K4: 张超 | L4: 推广 | M4: 推广 | N4: 推广 | O4: 客服 | P4: 客服 | Q4: 客服 | R4: 直播 | S4: 直播 | T4: 直播 | U4: 直播 | V4: 运营 | W4: 运营 | X4: 运营 | Y4: 运营 | Z4: 运营 | AA4: 运营 | AB4: 运营 | AC4: 运营 | AD4: 运营 | AE4: 运营 | AF4: 运营 | AG4: 运营 | AH4: 运营 | AI4: 运营 | AJ4: 运营 | AK4: 运营 | AL4: 运营 | AM4: 运营 | AN4: 运营 | AO4: 运营 | AP4: 运营 | AQ4: 运营 | AR4: 运营 | AS4: 运营 | AT4: 客服 | AU4: 客服 | AV4: 客服 | AW4: 客服 | AX4: 客服 | AY4: 客服 | AZ4: 客服 | BA4: 客服 | BB4: 客服 | BC4: 客服 | BD4: 客服 | BE4: 客服 | BF4: 客服 | BG4: 客服 | BH4: 供应链 | BI4: 运营 | BJ4: 运营 | BK4: 运营 | BL4: 运营 | BM4: 运营 | BN4: 运营 | BO4: 运营 | BP4: 运营 | BQ4: 运营 | BR4: 运营 | BS4: 运营 | BT4: 运营 | BU4: 运营 | BV4: 运营 | BW4: 运营 | BX4: 运营 | BY4: 运营 | BZ4: 运营 | CA4: 运营 | CB4: 运营 | CC4: 运营 | CD4: 运营 | CE4: 运营 | CF4: 运营
A5: 45108 | B5: A | C5: 无 | F5: 5.5081 | H5: =IFERROR(E5/G5-1,"") | I5: 5.2784 | J5: =IFERROR(E5/I5,"") | K5: =IFERROR(E5/#REF!,"") | L5: 43345 | M5: - | R5: 0 | S5: 0 | W5: - | Y5: - | AA5: - | AC5: - | AD5: 18 | AE5: - | AG5: - | AH5: 1291 | AI5: - | AJ5: 262 | AK5: - | AL5: 33 | AM5: - | AN5: 12 | AO5: - | AP5: 591 | AQ5: - | AR5: 169 | AS5: - | AT5: 0.0122 | AU5: - | BH5: 1 | BI5: E | BJ5: 85 | BK5: 877 | BL5: - | BM5: F | BN5: 383 | BO5: 342 | BP5: -
A6: 45109 | B6: A | C6: 无 | F6: 4.6384 | H6: =IFERROR(E6/G6-1,"") | I6: 5.6086 | J6: =IFERROR(E6/I6,"") | K6: =IFERROR(E6/#REF!,"") | L6: 18394 | M6: - | R6: 2899 | S6: 0 | W6: - | Y6: - | AA6: - | AC6: - | AD6: 12 | AE6: - | AG6: - | AH6: 1461 | AI6: - | AJ6: 327 | AK6: - | AL6: 39 | AM6: - | AN6: 11 | AO6: - | AP6: 716 | AQ6: - | AR6: 173 | AS6: - | AT6: 0.0094 | AU6: - | BH6: 1 | BI6: E | BJ6: 66 | BK6: 1205 | BL6: - | BM6: F | BN6: 353 | BO6: 365 | BP6: -
A7: 45110 | B7: 预约 | C7: 无 | F7: 0 | H7: =IFERROR(E7/G7-1,"") | I7: 0 | J7: =IFERROR(E7/I7,"") | K7: =IFERROR(E7/#REF!,"") | L7: 10817 | M7: - | R7: 0 | S7: 0 | W7: - | Y7: - | AA7: - | AC7: - | AD7: 19 | AE7: - | AG7: - | AH7: 1221 | AI7: - | AJ7: 399 | AK7: - | AL7: 36 | AM7: - | AN7: 13 | AO7: - | AP7: 543 | AQ7: - | AR7: 156 | AS7: - | AT7: 0 | AU7: - | BH7: 1 | BI7: E | BJ7: 92 | BK7: 771 | BL7: - | BM7: F | BN7: 553 | BO7: 198 | BP7: - | BV7: 13QC05 | BW7: POP13QS04 | BX7: 16GD31 | BY7: 13GD32 | BZ7: 13QD31 | CA7: 13QD06W | CB7: POP13QC05 | CC7: 16QD31 | CD7: 16QD06W | CE7: 能率13EA2
A8: 45111 | B8: A | C8: 无 | F8: 11.3064 | H8: =IFERROR(E8/G8-1,"") | I8: 6.9279 | J8: =IFERROR(E8/I8,"") | K8: =IFERROR(E8/#REF!,"") | L8: 27091 | M8: - | R8: 0 | S8: 0 | W8: - | Y8: - | AA8: - | AC8: - | AD8: 33 | AE8: - | AG8: - | AH8: 1259 | AI8: - | AJ8: 378 | AK8: - | AL8: 35 | AM8: - | AN8: 16 | AO8: - | AP8: 525 | AQ8: - | AR8: 141 | AS8: - | AT8: 0.0256 | AU8: - | BH8: 1 | BI8: E | BJ8: 93 | BK8: 743 | BL8: - | BM8: F | BN8: 447 | BO8: 248 | BP8: -
A9: 45112 | B9: A | C9: 无 | F9: 8.687 | H9: =IFERROR(E9/G9-1,"") | I9: 10.5571 | J9: =IFERROR(E9/I9,"") | K9: =IFERROR(E9/#REF!,"") | L9: 44505 | M9: - | R9: 0 | S9: 0 | W9: - | Y9: - | AA9: - | AC9: - | AD9: 27 | AE9: - | AG9: - | AH9: 1459 | AI9: - | AJ9: 414 | AK9: - | AL9: 49 | AM9: - | AN9: 16 | AO9: - | AP9: 697 | AQ9: - | AR9: 119 | AS9: - | AT9: 0.0165 | AU9: - | BH9: 0.95 | BI9: E | BJ9: 68 | BK9: 961 | BL9: - | BM9: F | BN9: 319 | BO9: 357 | BP9: -
A10: 45113 | B10: 预约 | C10: 无 | F10: 0.2799 | H10: =IFERROR(E10/G10-1,"") | I10: 0.8998 | J10: =IFERROR(E10/I10,"") | K10: =IFERROR(E10/#REF!,"") | L10: 8757 | M10: - | R10: 0 | S10: 0 | W10: - | Y10: - | AA10: - | AC10: - | AD10: 22 | AE10: - | AG10: - | AH10: 973 | AI10: - | AJ10: 430 | AK10: - | AL10: 33 | AM10: - | AN10: 16 | AO10: - | AP10: 377 | AQ10: - | AR10: 113 | AS10: - | AT10: 0 | AU10: - | BH10: 0.95 | BI10: F | BJ10: 121 | BK10: 482 | BL10: - | BM10: F | BN10: 464 | BO10: 229 | BP10: -
A11: 45114 | B11: A | C11: 无 | F11: 8.697 | H11: =IFERROR(E11/G11-1,"") | I11: 8.9073 | J11: =IFERROR(E11/I11,"") | K11: =IFERROR(E11/#REF!,"") | L11: 28790 | M11: - | R11: 0 | S11: 0 | W11: - | Y11: - | AA11: - | AC11: - | AD11: 24 | AE11: - | AG11: - | AH11: 1219 | AI11: - | AJ11: 361 | AK11: - | AL11: 23 | AM11: - | AN11: 13 | AO11: - | AP11: 628 | AQ11: - | AR11: 91 | AS11: - | AT11: 0.0189 | AU11: - | BH11: 0.95 | BI11: E | BJ11: 90 | BK11: 684 | BL11: - | BM11: F | BN11: 427 | BO11: 233 | BP11: -
A12: 45115 | B12: A | C12: 无 | F12: 5.798 | H12: =IFERROR(E12/G12-1,"") | I12: 5.9385 | J12: =IFERROR(E12/I12,"") | K12: =IFERROR(E12/#REF!,"") | L12: 14405 | M12: - | R12: 0 | S12: 0 | W12: - | Y12: - | AA12: - | AC12: - | AD12: 24 | AE12: - | AG12: - | AH12: 1471 | AI12: - | AJ12: 468 | AK12: - | AL12: 41 | AM12: - | AN12: 11 | AO12: - | AP12: 799 | AQ12: - | AR12: 106 | AS12: - | AT12: 0.0111 | AU12: - | BH12: 0.93 | BI12: E | BJ12: 67 | BK12: 1041 | BL12: - | BM12: F | BN12: 267 | BO12: 470 | BP12: -
A13: 45116 | B13: 预约 | C13: 无 | F13: 0 | H13: =IFERROR(E13/G13-1,"") | I13: 0 | J13: =IFERROR(E13/I13,"") | K13: =IFERROR(E13/#REF!,"") | L13: 22082 | M13: - | R13: 0 | S13: 0 | W13: - | Y13: - | AA13: - | AC13: - | AD13: 32 | AE13: - | AG13: - | AH13: 1237 | AI13: - | AJ13: 503 | AK13: - | AL13: 28 | AM13: - | AN13: 12 | AO13: - | AP13: 511 | AQ13: - | AR13: 132 | AS13: - | AT13: 0 | AU13: - | BI13: E | BJ13: 98 | BK13: 741 | BL13: - | BM13: F | BN13: 574 | BO13: 192 | BP13: -
A14: 45117 | B14: 预约 | C14: 无 | F14: 0.5598 | H14: =IFERROR(E14/G14-1,"") | I14: 0 | J14: =IFERROR(E14/I14,"") | K14: =IFERROR(E14/#REF!,"") | L14: 15715 | M14: - | R14: 0 | S14: 0 | W14: - | Y14: - | AA14: - | AC14: - | AD14: 27 | AE14: - | AG14: - | AH14: 1008 | AI14: - | AJ14: 414 | AK14: - | AL14: 48 | AM14: - | AN14: 16 | AO14: - | AP14: 362 | AQ14: - | AR14: 114 | AS14: - | AT14: 0 | AU14: - | BH14: 0.95 | BI14: F | BJ14: 162 | BK14: 413 | BL14: - | BM14: F | BN14: 779 | BO14: 119 | BP14: -
A15: 45118 | B15: A | C15: 无 | F15: 7.8273 | H15: =IFERROR(E15/G15-1,"") | I15: 10.5568 | J15: =IFERROR(E15/I15,"") | K15: =IFERROR(E15/#REF!,"") | L15: 61678 | M15: - | R15: 2998 | S15: 0 | W15: - | Y15: - | AA15: - | AC15: - | AD15: 44 | AE15: - | AG15: - | AH15: 1129 | AI15: - | AJ15: 443 | AK15: - | AL15: 45 | AM15: - | AN15: 6 | AO15: - | AP15: 500 | AQ15: - | AR15: 146 | AS15: - | AT15: 0.018 | AU15: - | BI15: F | BJ15: 102 | BK15: 623 | BL15: - | BM15: F | BN15: 467 | BO15: 229 | BP15: - | BV15: 13QC05 | BW15: 13GD32 | BX15: 16GD31 | BY15: POP13QS04 | BZ15: 13QD31 | CA15: POP13QC05 | CB15: 13GD31 | CC15: 16QC05 | CD15: 13QD06W | CE15: 五星13QS04
A16: 45119 | B16: A | C16: 无 | F16: 4.6384 | H16: =IFERROR(E16/G16-1,"") | I16: 14.3 | J16: =IFERROR(E16/I16,"") | K16: =IFERROR(E16/#REF!,"") | L16: 27290 | M16: - | R16: 2899 | S16: 0 | W16: - | Y16: - | AA16: - | AC16: - | AD16: 37 | AE16: - | AG16: - | AH16: 1229 | AI16: - | AJ16: 335 | AK16: - | AL16: 37 | AM16: - | AN16: 13 | AO16: - | AP16: 592 | AQ16: - | AR16: 120 | AS16: - | AT16: 0.0109 | AU16: - | BH16: 1 | BI16: E | BJ16: 78 | BK16: 883 | BL16: - | BM16: F | BN16: 403 | BO16: 282 | BP16: -
A17: 45120 | B17: A | C17: 无 | F17: 8.697 | H17: =IFERROR(E17/G17-1,"") | I17: 11.7 | J17: =IFERROR(E17/I17,"") | K17: =IFERROR(E17/#REF!,"") | L17: 53304 | M17: - | R17: 11596 | S17: 0 | W17: - | Y17: - | AA17: - | AC17: - | AD17: 18 | AE17: - | AG17: - | AH17: 1295 | AI17: - | AJ17: 471 | AK17: - | AL17: 47 | AM17: - | AN17: 29 | AO17: - | AP17: 661 | AQ17: - | AR17: 114 | AS17: - | AT17: 0.0187 | AU17: - | BH17: 1 | BI17: E | BJ17: 78 | BK17: 893 | BL17: - | BM17: F | BN17: 440 | BO17: 254 | BP17: -
A18: 45121 | B18: 预售 | C18: 无 | F18: 0 | H18: =IFERROR(E18/G18-1,"") | I18: 0 | J18: =IFERROR(E18/I18,"") | K18: =IFERROR(E18/#REF!,"") | L18: 73478 | M18: - | R18: ？ | S18: 0 | W18: - | Y18: - | AA18: - | AC18: - | AD18: 28 | AE18: - | AG18: - | AH18: 1514 | AI18: - | AJ18: 665 | AK18: - | AL18: 60 | AM18: - | AN18: 18 | AO18: - | AP18: 805 | AQ18: - | AR18: 146 | AS18: - | AT18: 0 | AU18: - | BH18: 1 | BI18: E | BJ18: 70 | BK18: 936 | BL18: - | BM18: F | BN18: 393 | BO18: 301 | BP18: -
A19: 45122 | B19: 预售 | C19: 无 | F19: 0 | H19: =IFERROR(E19/G19-1,"") | I19: 0 | J19: =IFERROR(E19/I19,"") | K19: =IFERROR(E19/#REF!,"") | L19: 70076 | M19: - | R19: 0 | S19: 0 | W19: - | Y19: - | AA19: - | AC19: - | AD19: 26 | AE19: - | AG19: - | AH19: 1804 | AI19: - | AJ19: 726 | AK19: - | AL19: 64 | AM19: - | AN19: 26 | AO19: - | AP19: 1041 | AQ19: - | AR19: 120 | AS19: - | AT19: 0 | AU19: - | BI19: E | BJ19: 61 | BK19: 1155 | BL19: - | BM19: F | BN19: 241 | BO19: 509 | BP19: -
A20: 45123 | B20: S | C20: 无 | F20: 22.1923 | H20: =IFERROR(E20/G20-1,"") | I20: 36.4 | J20: =IFERROR(E20/I20,"") | K20: =IFERROR(E20/#REF!,"") | L20: 71151 | M20: - | R20: 0 | S20: 0 | W20: - | Y20: - | AA20: - | AC20: - | AD20: 41 | AE20: - | AG20: - | AH20: 1368 | AI20: - | AJ20: 570 | AK20: - | AL20: 56 | AM20: - | AN20: 27 | AO20: - | AP20: 613 | AQ20: - | AR20: 87 | AS20: - | AT20: 0.0386 | AU20: - | BI20: F | BJ20: 101 | BK20: 713 | BL20: - | BM20: F | BN20: 881 | BO20: 170 | BP20: -
A21: 45124 | B21: S | C21: 无 | F21: 8.0472 | H21: =IFERROR(E21/G21-1,"") | I21: 23.4 | J21: =IFERROR(E21/I21,"") | K21: =IFERROR(E21/#REF!,"") | L21: 54312 | M21: - | R21: 0 | S21: 0 | W21: - | Y21: - | AA21: - | AC21: - | AD21: 21 | AE21: - | AG21: - | AH21: 1084 | AI21: - | AJ21: 452 | AK21: - | AL21: 50 | AM21: - | AN21: 21 | AO21: - | AP21: 446 | AQ21: - | AR21: 49 | AS21: - | AT21: 0.0149 | AU21: - | BH21: 0.7 | BI21: F | BJ21: 141 | BK21: 457 | BL21: - | BM21: F | BN21: 1306 | BO21: 106 | BP21: -
A22: 45125 | B22: A | C22: 无 | F22: 3.4288 | H22: =IFERROR(E22/G22-1,"") | I22: 11.7 | J22: =IFERROR(E22/I22,"") | K22: =IFERROR(E22/#REF!,"") | L22: 61073 | M22: - | R22: 2899 | S22: 0 | W22: - | Y22: - | AA22: - | AC22: - | AD22: 19 | AE22: - | AG22: - | AH22: 989 | AI22: - | AJ22: 457 | AK22: - | AL22: 41 | AM22: - | AN22: 22 | AO22: - | AP22: 436 | AQ22: - | AR22: 58 | AS22: - | AT22: 0.0054 | AU22: - | BH22: 0.85 | BI22: F | BJ22: 144 | BK22: 442 | BL22: - | BM22: F | BN22: 762 | BO22: 152 | BP22: - | BV22: 13QC05 | BW22: 16GD31 | BX22: POP13QS04 | BY22: 13GD32 | BZ22: 13QD31 | CA22: 13QD06W | CB22: 海尔锦绣 | CC22: 16GD32 | CD22: 16QD31 | CE22: 五星13QS04
A23: 45126 | B23: A | C23: 无 | F23: 4.2845 | H23: =IFERROR(E23/G23-1,"") | I23: 0 | J23: =IFERROR(E23/I23,"") | K23: =IFERROR(E23/#REF!,"") | L23: 63908 | M23: - | R23: 2899 | S23: 0 | W23: - | Y23: - | AA23: - | AC23: - | AD23: 15 | AE23: - | AG23: - | AH23: 946 | AI23: - | AJ23: 411 | AK23: - | AL23: 40 | AM23: - | AN23: 9 | AO23: - | AP23: 392 | AQ23: - | AR23: 60 | AS23: - | AT23: 0.0082 | AU23: - | BH23: 1 | BI23: F | BJ23: 172 | BK23: 373 | BL23: - | BM23: F | BN23: 1064 | BO23: 108 | BP23: -
A24: 45127 | B24: A | C24: 无 | F24: 6.2818 | H24: =IFERROR(E24/G24-1,"") | I24: 22.1 | J24: =IFERROR(E24/I24,"") | K24: =IFERROR(E24/#REF!,"") | L24: 285852 | M24: - | R24: 2899 | S24: 0 | W24: - | Y24: - | AA24: - | AC24: - | AD24: 17 | AE24: - | AG24: - | AH24: 982 | AI24: - | AJ24: 450 | AK24: - | AL24: 27 | AM24: - | AN24: 20 | AO24: - | AP24: 407 | AQ24: - | AR24: 48 | AS24: - | AT24: 0.0139 | AU24: - | BH24: 1 | BI24: F | BJ24: 171 | BK24: 382 | BL24: - | BM24: F | BN24: 853 | BO24: 112 | BP24: -
A25: 45128 | B25: A | C25: 无 | F25: 8.669 | H25: =IFERROR(E25/G25-1,"") | I25: 16.9 | J25: =IFERROR(E25/I25,"") | K25: =IFERROR(E25/#REF!,"") | L25: 678109 | M25: - | R25: 2759 | S25: 0 | W25: - | Y25: - | AA25: - | AC25: - | AD25: 16 | AE25: - | AG25: - | AH25: 1205 | AI25: - | AJ25: 566 | AK25: - | AL25: 41 | AM25: - | AN25: 889 | AO25: - | AP25: 602 | AQ25: - | AR25: 73 | AS25: - | AT25: 0.0108 | AU25: - | BH25: 1 | BI25: F | BJ25: 101 | BK25: 597 | BL25: - | BM25: F | BN25: 413 | BO25: 268 | BP25: -
A26: 45129 | B26: 预售 | C26: 无 | F26: 0.8397 | H26: =IFERROR(E26/G26-1,"") | I26: 11.7 | J26: =IFERROR(E26/I26,"") | K26: =IFERROR(E26/#REF!,"") | L26: 71757 | M26: - | R26: 0 | S26: 0 | W26: - | Y26: - | AA26: - | AC26: - | AD26: 25 | AE26: - | AG26: - | AH26: 1760 | AI26: - | AJ26: 764 | AK26: - | AL26: 54 | AM26: - | AN26: 2209 | AO26: - | AP26: 934 | AQ26: - | AR26: 111 | AS26: - | AT26: 0 | AU26: - | BI26: E | BJ26: 60 | BK26: 1152 | BL26: - | BM26: F | BN26: 293 | BO26: 445 | BP26: -
A27: 45130 | B27: 预售 | C27: 无 | F27: 0 | H27: =IFERROR(E27/G27-1,"") | I27: 0 | J27: =IFERROR(E27/I27,"") | K27: =IFERROR(E27/#REF!,"") | L27: 85972 | M27: - | R27: 8697 | S27: 0 | W27: - | Y27: - | AA27: - | AC27: - | AD27: 26 | AE27: - | AG27: - | AH27: 1940 | AI27: - | AJ27: 931 | AK27: - | AL27: 80 | AM27: - | AN27: 823 | AO27: - | AP27: 1140 | AQ27: - | AR27: 130 | AS27: - | AT27: 0 | AU27: - | BI27: E | BJ27: 58 | BK27: 1364 | BL27: - | BM27: F | BN27: 303 | BO27: 410 | BP27: -
A28: 45131 | B28: 预售 | C28: 无 | F28: 30.8233 | H28: =IFERROR(E28/G28-1,"") | I28: 23.4 | J28: =IFERROR(E28/I28,"") | K28: =IFERROR(E28/#REF!,"") | L28: 132042 | M28: - | R28: 22712 | S28: 0 | W28: - | Y28: - | AA28: - | AC28: - | AD28: 18 | AE28: - | AG28: - | AH28: 1812 | AI28: - | AJ28: 722 | AK28: - | AL28: 76 | AM28: - | AN28: 1842 | AO28: - | AP28: 937 | AQ28: - | AR28: 117 | AS28: - | AT28: 0.0258 | AU28: - | BH28: 1 | BI28: E | BJ28: 60 | BK28: 1233 | BL28: - | BM28: F | BN28: 345 | BO28: 342 | BP28: -
A29: 45132 | B29: S | C29: 无 | F29: 19.0114 | H29: =IFERROR(E29/G29-1,"") | I29: 18.2 | J29: =IFERROR(E29/I29,"") | K29: =IFERROR(E29/#REF!,"") | L29: 90986 | M29: - | R29: 8697 | S29: 0 | W29: - | Y29: - | AA29: - | AC29: - | AD29: 24 | AE29: - | AG29: - | AH29: 1662 | AI29: - | AJ29: 257 | AK29: - | AL29: 64 | AM29: - | AN29: 906 | AO29: - | AP29: 924 | AQ29: - | AR29: 96 | AS29: - | AT29: 0.0223 | AU29: - | BH29: 1 | BI29: D | BJ29: 48 | BK29: 1285 | BL29: - | BM29: F | BN29: 285 | BO29: 405 | BP29: - | BV29: 13QC05 | BW29: 16GD31 | BX29: 五星13QS04 | BY29: 13GD32 | BZ29: 16GD32 | CA29: 厂直16GD32 | CB29: 16QC05 | CC29: 13QD31 | CD29: 16QD06W | CE29: 厂直16QC05
A30: 45133 | B30: A | C30: 无 | F30: 18.5839 | H30: =IFERROR(E30/G30-1,"") | I30: 10.4 | J30: =IFERROR(E30/I30,"") | K30: =IFERROR(E30/#REF!,"") | L30: 72281 | M30: - | R30: 8697 | S30: 0 | W30: - | Y30: - | AA30: - | AC30: - | AD30: 18 | AE30: - | AG30: - | AH30: 1784 | AI30: - | AJ30: 414 | AK30: - | AL30: 52 | AM30: - | AN30: 1044 | AO30: - | AP30: 1036 | AQ30: - | AR30: 113 | AS30: - | AT30: 0.0173 | AU30: - | BI30: D | BJ30: 37 | BK30: 1538 | BL30: - | BM30: F | BN30: 229 | BO30: 518 | BP30: -
A31: 45134 | B31: A | C31: 无 | F31: 19.5434 | H31: =IFERROR(E31/G31-1,"") | I31: 13 | J31: =IFERROR(E31/I31,"") | K31: =IFERROR(E31/#REF!,"") | L31: 89573 | M31: - | R31: 8557 | S31: 0 | W31: - | Y31: - | AA31: - | AC31: - | AD31: 19 | AE31: - | AG31: - | AH31: 1747 | AI31: - | AJ31: 603 | AK31: - | AL31: 63 | AM31: - | AN31: 1569 | AO31: - | AP31: 998 | AQ31: - | AR31: 136 | AS31: - | AT31: 0.0138 | AU31: - | BH31: 1 | BI31: D | BJ31: 47 | BK31: 1233 | BL31: - | BM31: F | BN31: 252 | BO31: 480 | BP31: -
A32: 45135 | B32: A | C32: 无 | F32: 16.3886 | H32: =IFERROR(E32/G32-1,"") | I32: 13 | J32: =IFERROR(E32/I32,"") | K32: =IFERROR(E32/#REF!,"") | L32: 111514 | M32: - | R32: 8417 | S32: 0 | W32: - | Y32: - | AA32: - | AC32: - | AD32: 17 | AE32: - | AG32: - | AH32: 1902 | AI32: - | AJ32: 512 | AK32: - | AL32: 48 | AM32: - | AN32: 1345 | AO32: - | AP32: 1085 | AQ32: - | AR32: 128 | AS32: - | AT32: 0.0158 | AU32: - | BH32: 1 | BI32: D | BJ32: 42 | BK32: 1351 | BL32: - | BM32: F | BN32: 219 | BO32: 542 | BP32: -
A33: 45136 | B33: 预售 | C33: 无 | F33: 0.6234 | H33: =IFERROR(E33/G33-1,"") | I33: 0 | J33: =IFERROR(E33/I33,"") | K33: =IFERROR(E33/#REF!,"") | L33: 70469 | M33: - | R33: 0 | S33: 0 | W33: - | Y33: - | AA33: - | AC33: - | AD33: 32 | AE33: - | AG33: - | AH33: 2303 | AI33: - | AJ33: 593 | AK33: - | AL33: 85 | AM33: - | AN33: 1508 | AO33: - | AP33: 1355 | AQ33: - | AR33: 226 | AS33: - | AT33: 0.0002 | AU33: - | BI33: D | BJ33: 42 | BK33: 1666 | BL33: - | BM33: F | BN33: 198 | BO33: 616 | BP33: -
A34: 45137 | B34: 预售 | C34: 无 | F34: 0 | H34: =IFERROR(E34/G34-1,"") | I34: 0 | J34: =IFERROR(E34/I34,"") | K34: =IFERROR(E34/#REF!,"") | L34: 85772 | M34: - | O34: 25.8011 | P34: / | Q34: 0.2352 | R34: 0 | S34: 0 | W34: - | Y34: - | AA34: - | AC34: - | AD34: 20 | AE34: - | AG34: - | AH34: 1899 | AI34: - | AJ34: 703 | AK34: - | AL34: 42 | AM34: - | AN34: 32 | AO34: - | AP34: 2273 | AQ34: - | AR34: 459 | AS34: - | AT34: 0 | AU34: - | AV34: 490 | AW34: - | AY34: - | AZ34: 98 | BA34: - | BB34: 0.2 | BC34: - | BH34: 0.8 | BI34: D | BJ34: 35 | BK34: 2169 | BL34: - | BM34: F | BN34: 199 | BO34: 665 | BP34: -
A35: 45138 | B35: 限时 | C35: 无 | F35: =50.5609-3.2 -> 47.3609 | H35: =IFERROR(E35/G35-1,"") | I35: 33 | J35: =IFERROR(E35/I35,"") | K35: =IFERROR(E35/#REF!,"") | L35: 143553 | M35: - | R35: 25811 | S35: 0 | W35: - | Y35: - | AA35: - | AC35: - | AD35: 27 | AE35: - | AG35: - | AH35: 2932 | AI35: - | AJ35: 996 | AK35: - | AL35: 96 | AM35: - | AN35: 1034 | AO35: - | AP35: 1801 | AQ35: - | AR35: 279 | AS35: - | AT35: 0.0359 | AU35: - | BH35: 1 | BI35: D | BJ35: 31 | BK35: 2349 | BL35: - | BM35: F | BN35: 171 | BO35: 721 | BP35: -
A36: 45139 | B36: S级 | C36: 无 | F36: =E36-2.8 -> #VALUE! | I36: 16 | J36: =IFERROR(E36/I36,"") | K36: =IFERROR(E36/#REF!,"") | L36: 131255 | M36: - | O36: 9.566 | R36: 3299 | W36: - | Y36: - | AA36: - | AC36: - | AD36: 10 | AE36: - | AG36: - | AH36: 2416 | AI36: - | AJ36: 642 | AK36: - | AL36: 78 | AM36: - | AN36: 1399 | AO36: - | AP36: 1426 | AQ36: - | AR36: 156 | AS36: - | AT36: 0.01845 | AV36: 175 | AW36: - | AX36: 0.0414 | AY36: - | BH36: 0.8 | BI36: D | BJ36: 29 | BK36: 2116 | BL36: - | BM36: F | BN36: 170 | BO36: 739 | BP36: - | BV36: 16GD31 | BW36: 13QC05 | BX36: 13GD32 | BY36: 五星13QS04 | BZ36: 16QC05 | CA36: 13GD32 | CB36: 海尔锦绣 | CC36: 13QD31 | CD36: 13QD06W | CE36: 16QD31
A37: 45140 | B37: A级 | C37: 无 | F37: =E37-1.7 -> #VALUE! | I37: 10 | J37: =IFERROR(E37/I37,"") | K37: =IFERROR(E37/#REF!,"") | L37: 125161 | M37: - | W37: - | Y37: - | AA37: - | AC37: - | AD37: 12 | AE37: - | AG37: - | AH37: 2767 | AI37: - | AJ37: 635 | AK37: - | AL37: 78 | AM37: - | AN37: 1116 | AO37: - | AP37: 1753 | AQ37: - | AR37: 248 | AS37: - | AT37: 0.0138 | BH37: 1 | BI37: D | BJ37: 21 | BK37: 2881 | BL37: - | BM37: F | BN37: 152 | BO37: 799 | BP37: - | BY37: 五星13QS04
A38: 45141 | B38: A级 | C38: 无 | F38: =E38-1.7 -> #VALUE! | I38: 9 | J38: =IFERROR(E38/I38,"") | K38: =IFERROR(E38/#REF!,"") | L38: 113436 | M38: - | W38: - | Y38: - | AA38: - | AC38: - | AD38: 17 | AE38: - | AG38: - | AH38: 2657 | AI38: - | AJ38: 620 | AK38: - | AL38: 80 | AM38: - | AN38: 4352 | AO38: - | AP38: 1504 | AQ38: - | AR38: 208 | AS38: - | AT38: 0.0058 | BH38: 1 | BI38: D | BJ38: 30 | BK38: 2206 | BL38: - | BM38: F | BN38: 187 | BO38: 674 | BP38: - | BY38: 五星13QS04
A39: 45142 | B39: A级 | C39: 无 | F39: =E39-1.9 -> #VALUE! | I39: 11 | J39: =IFERROR(E39/I39,"") | K39: =IFERROR(E39/#REF!,"") | L39: 70027 | M39: - | W39: - | Y39: - | AA39: - | AC39: - | AD39: 18 | AE39: - | AG39: - | AH39: 3037 | AI39: - | AJ39: 665 | AK39: - | AL39: 90 | AM39: - | AN39: 1181 | AO39: - | AP39: 1806 | AQ39: - | AR39: 249 | AS39: - | BH39: 0.95 | BI39: D | BJ39: 26 | BK39: 2383 | BL39: - | BM39: F | BN39: 144 | BO39: 837 | BP39: - | BY39: 五星13QS04
A40: 45143 | B40: 预售 | C40: 无 | F40: =E40 | I40: 0 | J40: =IFERROR(E40/I40,"") | K40: =IFERROR(E40/#REF!,"") | L40: 55948 | M40: - | W40: - | Y40: - | AA40: - | AC40: - | AD40: 19 | AE40: - | AG40: - | AH40: 3019 | AI40: - | AJ40: 865 | AK40: - | AL40: 105 | AM40: - | AN40: 861 | AO40: - | AP40: 1786 | AQ40: - | AR40: 327 | AS40: - | BH40: 0.85 | BI40: D | BJ40: 27 | BK40: 2433 | BL40: - | BM40: F | BN40: 139 | BO40: 938 | BP40: - | BY40: 五星13QS04
...

Sheet 单品16GD31 
A1: 7月 sku:100039707007 | D1: 销售出库 | V1: 流量 | AT1: 转化 | BH1: 京仓现货率 | BI1: 关键词排名 | BQ1: 流失分析 | CF1: 负同比每日分析
A2: 日期 | B2: 价格政策 | D2: 销售额 | L2: 模块销售占比 | V2: PV | X2: UV | Z2: 人均浏览量 | AB2: 平均停留时间 | AD2: 关注人数 | AF2: 加购人数 | AH2: 站内免费 | AJ2: 站内付费 | AL2: 站外免费 | AN2: 站外付费 | AP2: 搜索 | AR2: 内容 | AT2: 店铺转化率 | AV2: 询单 数 | AX2: 询单 率 | AZ2: 询单 成交数 | BB2: 询单 转化 | BD2: 静默成交数 | BF2: 静默转化 | BI2: 燃气热水器 | BM2: 热水器 | BQ2: 流量流失 | BV2: 销售流失
B3: Y-23 | C3: Y-22 | D3: Y-23 数量 | E3: Y-23 金额 | F3: 实际销售 | G3: Y-22 金额 | H3: 同比 | I3: 目标 | J3: 达成率 | K3: 类目占比 | L3: 推广成交金额 | M3: 同比 | N3: 占比 | O3: 客服成交金额 | P3: 同比 | Q3: 占比 | R3: Y-23 | S3: Y-22 | T3: 同比 | U3: 占比 | V3: Y-23 | W3: Y-22 | X3: Y-23 | Y3: Y-22 | Z3: Y-23 | AA3: Y-22 | AB3: Y-23 | AC3: Y-22 | AD3: Y-23 | AE3: Y-22 | AF3: Y-23 | AG3: Y-22 | AH3: Y-23 | AI3: Y-22 | AJ3: Y-23 | AK3: Y-22 | AL3: Y-23 | AM3: Y-22 | AN3: Y-23 | AO3: Y-22 | AP3: Y-23 | AQ3: Y-22 | AR3: Y-23 | AS3: Y-22 | AT3: Y-23 | AU3: Y-22 | AV3: Y-23 | AW3: Y-22 | AX3: Y-23 | AY3: Y-22 | AZ3: Y-23 | BA3: Y-22 | BB3: Y-23 | BC3: Y-22 | BD3: Y-23 | BE3: Y-22 | BF3: Y-23 | BG3: Y-22 | BI3: 层级 | BJ3: 排名 | BK3: 搜索曝光 | BL3: Y-22搜索曝光 | BM3: 层级 | BN3: 排名 | BO3: 搜索曝光 | BP3: Y-22搜索曝光 | BQ3: TOP 1 | BR3: TOP 2 | BS3: TOP 3 | BT3: TOP 4 | BU3: TOP 5 | BV3: TOP 1 | BW3: TOP 2 | BX3: TOP 3 | BY3: TOP 4 | BZ3: TOP 5 | CA3: TOP 6 | CB3: TOP 7 | CC3: TOP 8 | CD3: TOP 9 | CE3: TOP 10
A4: 填写人员 | B4: 运营 | C4: 运营 | D4: 张超 | E4: 张超 | F4: 运营 | G4: 张超 | H4: 张超 | I4: 张超 | J4: 张超 | K4: 张超 | L4: 推广 | M4: 推广 | N4: 推广 | O4: 客服 | P4: 客服 | Q4: 客服 | R4: 直播 | S4: 直播 | T4: 直播 | U4: 直播 | V4: 运营 | W4: 运营 | X4: 运营 | Y4: 运营 | Z4: 运营 | AA4: 运营 | AB4: 运营 | AC4: 运营 | AD4: 运营 | AE4: 运营 | AF4: 运营 | AG4: 运营 | AH4: 运营 | AI4: 运营 | AJ4: 运营 | AK4: 运营 | AL4: 运营 | AM4: 运营 | AN4: 运营 | AO4: 运营 | AP4: 运营 | AQ4: 运营 | AR4: 运营 | AS4: 运营 | AT4: 客服 | AU4: 客服 | AV4: 客服 | AW4: 客服 | AX4: 客服 | AY4: 客服 | AZ4: 客服 | BA4: 客服 | BB4: 客服 | BC4: 客服 | BD4: 客服 | BE4: 客服 | BF4: 客服 | BG4: 客服 | BH4: 供应链 | BI4: 运营 | BJ4: 运营 | BK4: 运营 | BL4: 运营 | BM4: 运营 | BN4: 运营 | BO4: 运营 | BP4: 运营 | BQ4: 运营 | BR4: 运营 | BS4: 运营 | BT4: 运营 | BU4: 运营 | BV4: 运营 | BW4: 运营 | BX4: 运营 | BY4: 运营 | BZ4: 运营 | CA4: 运营 | CB4: 运营 | CC4: 运营 | CD4: 运营 | CE4: 运营 | CF4: 运营
A5: 45108 | B5: A | C5: 无 | F5: 5.5983 | H5: =IFERROR(E5/G5-1,"") | I5: 5.2784 | J5: =IFERROR(E5/I5,"") | K5: =IFERROR(E5/#REF!,"") | L5: 44368 | M5: - | R5: 6598 | S5: 0 | W5: - | Y5: - | AA5: - | AC5: - | AD5: 8 | AE5: - | AG5: - | AH5: 1344 | AI5: - | AJ5: 528 | AK5: - | AL5: 44 | AM5: - | AN5: 32 | AO5: - | AP5: 644 | AQ5: - | AR5: 85 | AS5: - | AT5: 0.0086 | AU5: - | BH5: 1 | BI5: E | BJ5: 100 | BK5: 735 | BL5: - | BM5: F | BN5: 451 | BO5: 281 | BP5: -
A6: 45109 | B6: A | C6: 无 | F6: 5.9285 | H6: =IFERROR(E6/G6-1,"") | I6: 5.6086 | J6: =IFERROR(E6/I6,"") | K6: =IFERROR(E6/#REF!,"") | L6: 28923 | M6: - | R6: 3299 | S6: 0 | W6: - | Y6: - | AA6: - | AC6: - | AD6: 13 | AE6: - | AG6: - | AH6: 1424 | AI6: - | AJ6: 749 | AK6: - | AL6: 39 | AM6: - | AN6: 42 | AO6: - | AP6: 679 | AQ6: - | AR6: 103 | AS6: - | AT6: 0.0086 | AU6: - | BH6: 1 | BI6: E | BJ6: 82 | BK6: 1020 | BL6: - | BM6: F | BN6: 525 | BO6: 229 | BP6: -
A7: 45110 | B7: 预约 | C7: 无 | F7: 0.9597 | H7: =IFERROR(E7/G7-1,"") | I7: 0 | J7: =IFERROR(E7/I7,"") | K7: =IFERROR(E7/#REF!,"") | L7: 22490 | M7: - | R7: 0 | S7: 0 | W7: - | Y7: - | AA7: - | AC7: - | AD7: 16 | AE7: - | AG7: - | AH7: 1525 | AI7: - | AJ7: 785 | AK7: - | AL7: 59 | AM7: - | AN7: 36 | AO7: - | AP7: 635 | AQ7: - | AR7: 135 | AS7: - | AT7: 0 | AU7: - | BH7: 1 | BI7: E | BJ7: 90 | BK7: 776 | BL7: - | BM7: F | BN7: 567 | BO7: 191 | BP7: - | BV7: 16QD31 | BW7: 16GD32 | BX7: 海尔锦绣 | BY7: POP16GD32 | BZ7: 16QD06W | CA7: 13GD31 | CB7: 16QC05 | CC7: POP16QS04 | CD7: 16QD06 | CE7: 能率16EA2
A8: 45111 | B8: A | C8: 无 | F8: 6.9279 | H8: =IFERROR(E8/G8-1,"") | I8: 6.9279 | J8: =IFERROR(E8/I8,"") | K8: =IFERROR(E8/#REF!,"") | L8: 65680 | M8: - | R8: 9897 | S8: 0 | W8: - | Y8: - | AA8: - | AC8: - | AD8: 21 | AE8: - | AG8: - | AH8: 1595 | AI8: - | AJ8: 815 | AK8: - | AL8: 45 | AM8: - | AN8: 36 | AO8: - | AP8: 614 | AQ8: - | AR8: 151 | AS8: - | AT8: 0.0096 | AU8: - | BH8: 1 | BI8: E | BJ8: 90 | BK8: 767 | BL8: - | BM8: F | BN8: 519 | BO8: 207 | BP8: -
A9: 45112 | B9: A | C9: 无 | F9: 11.1969 | H9: =IFERROR(E9/G9-1,"") | I9: 10.5571 | J9: =IFERROR(E9/I9,"") | K9: =IFERROR(E9/#REF!,"") | L9: 59987 | M9: - | R9: 3299 | S9: 0 | W9: - | Y9: - | AA9: - | AC9: - | AD9: 7 | AE9: - | AG9: - | AH9: 1735 | AI9: - | AJ9: 498 | AK9: - | AL9: 53 | AM9: - | AN9: 29 | AO9: - | AP9: 769 | AQ9: - | AR9: 151 | AS9: - | AT9: 0.0147 | AU9: - | BH9: 1 | BI9: E | BJ9: 64 | BK9: 1031 | BL9: - | BM9: F | BN9: 335 | BO9: 340 | BP9: -
A10: 45113 | B10: 预约 | C10: 无 | F10: 1.2197 | H10: =IFERROR(E10/G10-1,"") | I10: 0.8998 | J10: =IFERROR(E10/I10,"") | K10: =IFERROR(E10/#REF!,"") | L10: 6158 | M10: - | R10: 0 | S10: 0 | W10: - | Y10: - | AA10: - | AC10: - | AD10: 7 | AE10: - | AG10: - | AH10: 1310 | AI10: - | AJ10: 649 | AK10: - | AL10: 72 | AM10: - | AN10: 39 | AO10: - | AP10: 468 | AQ10: - | AR10: 103 | AS10: - | AT10: 0.0011 | AU10: - | BH10: 1 | BI10: E | BJ10: 94 | BK10: 632 | BL10: - | BM10: F | BN10: 328 | BO10: 362 | BP10: -
A11: 45114 | B11: A | C11: 无 | F11: 9.2272 | H11: =IFERROR(E11/G11-1,"") | I11: 8.9073 | J11: =IFERROR(E11/I11,"") | K11: =IFERROR(E11/#REF!,"") | L11: 15695 | M11: - | R11: 3299 | S11: 0 | W11: - | Y11: - | AA11: - | AC11: - | AD11: 14 | AE11: - | AG11: - | AH11: 1575 | AI11: - | AJ11: 711 | AK11: - | AL11: 64 | AM11: - | AN11: 32 | AO11: - | AP11: 708 | AQ11: - | AR11: 105 | AS11: - | AT11: 0.0129 | AU11: - | BH11: 1 | BI11: E | BJ11: 77 | BK11: 882 | BL11: - | BM11: F | BN11: 418 | BO11: 240 | BP11: -
A12: 45115 | B12: A | C12: 无 | F12: 6.5783 | H12: =IFERROR(E12/G12-1,"") | I12: 5.9385 | J12: =IFERROR(E12/I12,"") | K12: =IFERROR(E12/#REF!,"") | L12: 16295 | M12: - | R12: 0 | S12: 0 | W12: - | Y12: - | AA12: - | AC12: - | AD12: 11 | AE12: - | AG12: - | AH12: 1701 | AI12: - | AJ12: 295 | AK12: - | AL12: 57 | AM12: - | AN12: 47 | AO12: - | AP12: 764 | AQ12: - | AR12: 109 | AS12: - | AT12: 0.0093 | AU12: - | BH12: 1 | BI12: E | BJ12: 69 | BK12: 1040 | BL12: - | BM12: F | BN12: 331 | BO12: 352 | BP12: -
A13: 45116 | B13: 预约 | C13: 无 | F13: 0.3199 | H13: =IFERROR(E13/G13-1,"") | I13: 0 | J13: =IFERROR(E13/I13,"") | K13: =IFERROR(E13/#REF!,"") | L13: 5467 | M13: - | R13: 0 | S13: 0 | W13: - | Y13: - | AA13: - | AC13: - | AD13: 24 | AE13: - | AG13: - | AH13: 1694 | AI13: - | AJ13: 701 | AK13: - | AL13: 76 | AM13: - | AN13: 49 | AO13: - | AP13: 721 | AQ13: - | AR13: 134 | AS13: - | AT13: 0 | AU13: - | BH13: 1 | BI13: E | BJ13: 97 | BK13: 755 | BL13: - | BM13: F | BN13: 594 | BO13: 185 | BP13: -
A14: 45117 | B14: 预约 | C14: 无 | F14: 0 | H14: =IFERROR(E14/G14-1,"") | I14: 0 | J14: =IFERROR(E14/I14,"") | K14: =IFERROR(E14/#REF!,"") | L14: 13519 | M14: - | R14: 0 | S14: 0 | W14: - | Y14: - | AA14: - | AC14: - | AD14: 23 | AE14: - | AG14: - | AH14: 1536 | AI14: - | AJ14: 787 | AK14: - | AL14: 49 | AM14: - | AN14: 44 | AO14: - | AP14: 530 | AQ14: - | AR14: 127 | AS14: - | AT14: 0 | AU14: - | BH14: 1 | BI14: F | BJ14: 117 | BK14: 538 | BL14: - | BM14: F | BN14: 747 | BO14: 128 | BP14: -
A15: 45118 | B15: A | C15: 无 | F15: 10.5568 | H15: =IFERROR(E15/G15-1,"") | I15: 10.5568 | J15: =IFERROR(E15/I15,"") | K15: =IFERROR(E15/#REF!,"") | L15: 78675 | M15: - | R15: 16495 | S15: 0 | W15: - | Y15: - | AA15: - | AC15: - | AD15: 22 | AE15: - | AG15: - | AH15: 1897 | AI15: - | AJ15: 759 | AK15: - | AL15: 56 | AM15: - | AN15: 58 | AO15: - | AP15: 690 | AQ15: - | AR15: 158 | AS15: - | AT15: 0.013 | AU15: - | BH15: 1 | BI15: E | BJ15: 83 | BK15: 764 | BL15: - | BM15: F | BN15: 443 | BO15: 246 | BP15: - | BV15: 16QD31 | BW15: 16QC05 | BX15: 16GD32 | BY15: 13GD31 | BZ15: 16QD06W | CA15: 海尔锦绣 | CB15: 16GD32 | CC15: 13QC05 | CD15: 海尔云程 | CE15: 13GD32
A16: 45119 | B16: A | C16: 无 | F16: 7.9179 | H16: =IFERROR(E16/G16-1,"") | I16: 14.3 | J16: =IFERROR(E16/I16,"") | K16: =IFERROR(E16/#REF!,"") | L16: 36089 | M16: - | R16: 0 | S16: 0 | W16: - | Y16: - | AA16: - | AC16: - | AD16: 20 | AE16: - | AG16: - | AH16: 1753 | AI16: - | AJ16: 791 | AK16: - | AL16: 94 | AM16: - | AN16: 30 | AO16: - | AP16: 804 | AQ16: - | AR16: 113 | AS16: - | AT16: 0.0102 | AU16: - | BH16: 1 | BI16: E | BJ16: 64 | BK16: 1054 | BL16: - | BM16: F | BN16: 402 | BO16: 282 | BP16: -
A17: 45120 | B17: A | C17: 无 | F17: 8.5777 | H17: =IFERROR(E17/G17-1,"") | I17: 11.7 | J17: =IFERROR(E17/I17,"") | K17: =IFERROR(E17/#REF!,"") | L17: 29447 | M17: - | R17: 6601 | S17: 0 | W17: - | Y17: - | AA17: - | AC17: - | AD17: 15 | AE17: - | AG17: - | AH17: 1879 | AI17: - | AJ17: 640 | AK17: - | AL17: 75 | AM17: - | AN17: 48 | AO17: - | AP17: 932 | AQ17: - | AR17: 123 | AS17: - | AT17: 0.0111 | AU17: - | BH17: 1 | BI17: E | BJ17: 55 | BK17: 1178 | BL17: - | BM17: F | BN17: 381 | BO17: 296 | BP17: -
A18: 45121 | B18: 预售 | C18: 无 | F18: 0.3199 | H18: =IFERROR(E18/G18-1,"") | I18: 0 | J18: =IFERROR(E18/I18,"") | K18: =IFERROR(E18/#REF!,"") | L18: 40655 | M18: - | R18: ？ | S18: 0 | W18: - | Y18: - | AA18: - | AC18: - | AD18: 22 | AE18: - | AG18: - | AH18: 2194 | AI18: - | AJ18: 783 | AK18: - | AL18: 73 | AM18: - | AN18: 45 | AO18: - | AP18: 1184 | AQ18: - | AR18: 168 | AS18: - | AT18: 0 | AU18: - | BH18: 1 | BI18: D | BJ18: 49 | BK18: 1328 | BL18: - | BM18: F | BN18: 273 | BO18: 431 | BP18: -
A19: 45122 | B19: 预售 | C19: 无 | F19: 0.3199 | H19: =IFERROR(E19/G19-1,"") | I19: 0 | J19: =IFERROR(E19/I19,"") | K19: =IFERROR(E19/#REF!,"") | L19: 31900 | M19: - | R19: 0 | S19: 0 | W19: - | Y19: - | AA19: - | AC19: - | AD19: 21 | AE19: - | AG19: - | AH19: 2138 | AI19: - | AJ19: 774 | AK19: - | AL19: 65 | AM19: - | AN19: 39 | AO19: - | AP19: 1215 | AQ19: - | AR19: 152 | AS19: - | AT19: 0 | AU19: - | BH19: 1 | BI19: D | BJ19: 49 | BK19: 1428 | BL19: - | BM19: F | BN19: 307 | BO19: 406 | BP19: -
A20: 45123 | B20: S | C20: 无 | F20: 30.5408 | H20: =IFERROR(E20/G20-1,"") | I20: 36.4 | J20: =IFERROR(E20/I20,"") | K20: =IFERROR(E20/#REF!,"") | L20: 102488 | M20: - | R20: 19794 | S20: 0 | W20: - | Y20: - | AA20: - | AC20: - | AD20: 26 | AE20: - | AG20: - | AH20: 2614 | AI20: - | AJ20: 795 | AK20: - | AL20: 75 | AM20: - | AN20: 46 | AO20: - | AP20: 1420 | AQ20: - | AR20: 187 | AS20: - | AT20: 0.029 | AU20: - | BH20: 1 | BI20: D | BJ20: 49 | BK20: 1577 | BL20: - | BM20: F | BN20: 327 | BO20: 433 | BP20: -
A21: 45124 | B21: S | C21: 无 | F21: 13.8558 | H21: =IFERROR(E21/G21-1,"") | I21: 23.4 | J21: =IFERROR(E21/I21,"") | K21: =IFERROR(E21/#REF!,"") | L21: 63421 | M21: - | R21: 13196 | S21: 0 | W21: - | Y21: - | AA21: - | AC21: - | AD21: 14 | AE21: - | AG21: - | AH21: 2371 | AI21: - | AJ21: 839 | AK21: - | AL21: 86 | AM21: - | AN21: 70 | AO21: - | AP21: 1267 | AQ21: - | AR21: 149 | AS21: - | AT21: 0.0138 | AU21: - | BH21: 1 | BI21: D | BJ21: 40 | BK21: 1256 | BL21: - | BM21: F | BN21: 320 | BO21: 418 | BP21: -
A22: 45125 | B22: A | C22: 无 | F22: 11.5825 | H22: =IFERROR(E22/G22-1,"") | I22: 11.7 | J22: =IFERROR(E22/I22,"") | K22: =IFERROR(E22/#REF!,"") | L22: 217755 | M22: - | R22: 0 | S22: 0 | W22: - | Y22: - | AA22: - | AC22: - | AD22: 18 | AE22: - | AG22: - | AH22: 2106 | AI22: - | AJ22: 205 | AK22: - | AL22: 77 | AM22: - | AN22: 59 | AO22: - | AP22: 1127 | AQ22: - | AR22: 144 | AS22: - | AT22: 0.0144 | AU22: - | BH22: 1 | BI22: D | BJ22: 50 | BK22: 1279 | BL22: - | BM22: F | BN22: 371 | BO22: 334 | BP22: - | BV22: 16QD06* | BW22: 16QD31 | BX22: 16GD32 | BY22: 16QC05 | BZ22: 海尔锦绣 | CA22: 13GD31 | CB22: 16QD06W | CC22: 16QD03* | CD22: 16QD06* | CE22: 13GD32
A23: 45126 | B23: A | C23: 无 | F23: 10.1789 | H23: =IFERROR(E23/G23-1,"") | I23: 0 | J23: =IFERROR(E23/I23,"") | K23: =IFERROR(E23/#REF!,"") | L23: 107294 | M23: - | R23: 6438 | S23: 0 | W23: - | Y23: - | AA23: - | AC23: - | AD23: 23 | AE23: - | AG23: - | AH23: 2272 | AI23: - | AJ23: 996 | AK23: - | AL23: 83 | AM23: - | AN23: 60 | AO23: - | AP23: 1203 | AQ23: - | AR23: 144 | AS23: - | AT23: 0.0104 | AU23: - | BH23: 1 | BI23: E | BJ23: 54 | BK23: 1289 | BL23: - | BM23: F | BN23: 331 | BO23: 357 | BP23: -
A24: 45127 | B24: A | C24: 无 | F24: 14.6096 | H24: =IFERROR(E24/G24-1,"") | I24: 22.1 | J24: =IFERROR(E24/I24,"") | K24: =IFERROR(E24/#REF!,"") | L24: 1342791 | M24: - | R24: 9897 | S24: 0 | W24: - | Y24: - | AA24: - | AC24: - | AD24: 22 | AE24: - | AG24: - | AH24: 2427 | AI24: - | AJ24: 1040 | AK24: - | AL24: 78 | AM24: - | AN24: 70 | AO24: - | AP24: 1322 | AQ24: - | AR24: 153 | AS24: - | AT24: 0.0136 | AU24: - | BH24: 1 | BI24: D | BJ24: 41 | BK24: 1558 | BL24: - | BM24: F | BN24: 252 | BO24: 478 | BP24: -
A25: 45128 | B25: A | C25: 无 | F25: 9.5191 | H25: =IFERROR(E25/G25-1,"") | I25: 16.9 | J25: =IFERROR(E25/I25,"") | K25: =IFERROR(E25/#REF!,"") | L25: 65063 | M25: - | R25: 3299 | S25: 0 | W25: - | Y25: - | AA25: - | AC25: - | AD25: 24 | AE25: - | AG25: - | AH25: 2069 | AI25: - | AJ25: 746 | AK25: - | AL25: 82 | AM25: - | AN25: 963 | AO25: - | AP25: 1081 | AQ25: - | AR25: 119 | AS25: - | AT25: 0.008 | AU25: - | BH25: 1 | BI25: E | BJ25: 54 | BK25: 1214 | BL25: - | BM25: F | BN25: 272 | BO25: 437 | BP25: -
A26: 45129 | B26: 预售 | C26: 无 | F26: 0.9797 | H26: =IFERROR(E26/G26-1,"") | I26: 11.7 | J26: =IFERROR(E26/I26,"") | K26: =IFERROR(E26/#REF!,"") | L26: 26992 | M26: - | R26: 0 | S26: 0 | W26: - | Y26: - | AA26: - | AC26: - | AD26: 28 | AE26: - | AG26: - | AH26: 2570 | AI26: - | AJ26: 926 | AK26: - | AL26: 71 | AM26: - | AN26: 2884 | AO26: - | AP26: 1350 | AQ26: - | AR26: 198 | AS26: - | AT26: 0.0003 | AU26: - | BH26: 1 | BI26: D | BJ26: 48 | BK26: 1389 | BL26: - | BM26: F | BN26: 295 | BO26: 443 | BP26: -
A27: 45130 | B27: 预售 | C27: 无 | F27: 0 | H27: =IFERROR(E27/G27-1,"") | I27: 0 | J27: =IFERROR(E27/I27,"") | K27: =IFERROR(E27/#REF!,"") | L27: 16696 | M27: - | R27: 0 | S27: 0 | W27: - | Y27: - | AA27: - | AC27: - | AD27: 21 | AE27: - | AG27: - | AH27: 2437 | AI27: - | AJ27: 126 | AK27: - | AL27: 89 | AM27: - | AN27: 1169 | AO27: - | AP27: 1310 | AQ27: - | AR27: 202 | AS27: - | AT27: 0 | AU27: - | BH27: 1 | BI27: D | BJ27: 44 | BK27: 1587 | BL27: - | BM27: F | BN27: 264 | BO27: 484 | BP27: -
A28: 45131 | B28: 预售 | C28: 无 | F28: 29.2171 | H28: =IFERROR(E28/G28-1,"") | I28: 23.4 | J28: =IFERROR(E28/I28,"") | K28: =IFERROR(E28/#REF!,"") | L28: 73807 | M28: - | R28: 26392 | S28: 0 | W28: - | Y28: - | AA28: - | AC28: - | AD28: 24 | AE28: - | AG28: - | AH28: 2870 | AI28: - | AJ28: 1009 | AK28: - | AL28: 120 | AM28: - | AN28: 3200 | AO28: - | AP28: 1582 | AQ28: - | AR28: 211 | AS28: - | AT28: 0.0134 | AU28: - | BH28: 1 | BI28: D | BJ28: 35 | BK28: 1778 | BL28: - | BM28: F | BN28: 243 | BO28: 496 | BP28: -
A29: 45132 | B29: S | C29: 无 | F29: 31.5665 | H29: =IFERROR(E29/G29-1,"") | I29: 18.2 | J29: =IFERROR(E29/I29,"") | K29: =IFERROR(E29/#REF!,"") | L29: 64783 | M29: - | R29: 91973 | S29: 0 | W29: - | Y29: - | AA29: - | AC29: - | AD29: 20 | AE29: - | AG29: - | AH29: 2692 | AI29: - | AJ29: 680 | AK29: - | AL29: 134 | AM29: - | AN29: 3296 | AO29: - | AP29: 1301 | AQ29: - | AR29: 152 | AS29: - | AT29: 0.0111 | AU29: - | BH29: 1 | BI29: D | BJ29: 39 | BK29: 1479 | BL29: - | BM29: F | BN29: 245 | BO29: 476 | BP29: - | BV29: 16GD32 | BW29: 16QD31 | BX29: 13GD31 | BY29: 16QD06W | BZ29: 16QC05 | CA29: 海尔锦绣 | CB29: 五星16GD32 | CC29: 五星16QC06 | CD29: 海尔云程 | CE29: 13GD32
A30: 45133 | B30: A | C30: 无 | F30: 14.9135 | H30: =IFERROR(E30/G30-1,"") | I30: 10.4 | J30: =IFERROR(E30/I30,"") | K30: =IFERROR(E30/#REF!,"") | L30: 103749 | M30: - | R30: 9897 | S30: 0 | W30: - | Y30: - | AA30: - | AC30: - | AD30: 18 | AE30: - | AG30: - | AH30: 2494 | AI30: - | AJ30: 767 | AK30: - | AL30: 74 | AM30: - | AN30: 2854 | AO30: - | AP30: 1195 | AQ30: - | AR30: 160 | AS30: - | AT30: 0.0075 | AU30: - | BH30: 1 | BI30: D | BJ30: 38 | BK30: 1451 | BL30: - | BM30: F | BN30: 240 | BO30: 483 | BP30: -
A31: 45134 | B31: A | C31: 无 | F31: 17.8236 | H31: =IFERROR(E31/G31-1,"") | I31: 13 | J31: =IFERROR(E31/I31,"") | K31: =IFERROR(E31/#REF!,"") | L31: 40088 | M31: - | R31: 3299 | S31: 0 | W31: - | Y31: - | AA31: - | AC31: - | AD31: 12 | AE31: - | AG31: - | AH31: 2499 | AI31: - | AJ31: 225 | AK31: - | AL31: 77 | AM31: - | AN31: 5601 | AO31: - | AP31: 1196 | AQ31: - | AR31: 181 | AS31: - | AT31: 0.0064 | AU31: - | BH31: 1 | BI31: D | BJ31: 44 | BK31: 1273 | BL31: - | BM31: F | BN31: 269 | BO31: 446 | BP31: -
A32: 45135 | B32: A | C32: 无 | F32: 11.4668 | H32: =IFERROR(E32/G32-1,"") | I32: 13 | J32: =IFERROR(E32/I32,"") | K32: =IFERROR(E32/#REF!,"") | L32: 38898 | M32: - | R32: 6598 | S32: 0 | W32: - | Y32: - | AA32: - | AC32: - | AD32: 24 | AE32: - | AG32: - | AH32: 2412 | AI32: - | AJ32: 636 | AK32: - | AL32: 57 | AM32: - | AN32: 3357 | AO32: - | AP32: 1163 | AQ32: - | AR32: 149 | AS32: - | AT32: 0.0058 | AU32: - | BH32: 1 | BI32: E | BJ32: 51 | BK32: 1119 | BL32: - | BM32: F | BN32: 306 | BO32: 368 | BP32: -
A33: 45136 | B33: 预售 | C33: 无 | F33: 0 | H33: =IFERROR(E33/G33-1,"") | I33: 0 | J33: =IFERROR(E33/I33,"") | K33: =IFERROR(E33/#REF!,"") | L33: 47101 | M33: - | R33: 0 | S33: 0 | W33: - | Y33: - | AA33: - | AC33: - | AD33: 24 | AE33: - | AG33: - | AH33: 3016 | AI33: - | AJ33: 599 | AK33: - | AL33: 98 | AM33: - | AN33: 4056 | AO33: - | AP33: 1580 | AQ33: - | AR33: 270 | AS33: - | AT33: 0 | AU33: - | BH33: 1 | BI33: D | BJ33: 43 | BK33: 1521 | BL33: - | BM33: F | BN33: 258 | BO33: 479 | BP33: -
A34: 45137 | B34: 预售 | C34: 无 | F34: 0 | H34: =IFERROR(E34/G34-1,"") | I34: 0 | J34: =IFERROR(E34/I34,"") | K34: =IFERROR(E34/#REF!,"") | L34: 36289 | M34: - | O34: 23.8327 | P34: 0 | Q34: 0.2173 | R34: 0 | S34: 0 | W34: - | Y34: - | AA34: - | AC34: - | AD34: 27 | AE34: - | AG34: - | AH34: 3504 | AI34: - | AJ34: 754 | AK34: - | AL34: 86 | AM34: - | AN34: 1873 | AO34: - | AP34: 2108 | AQ34: - | AR34: 328 | AS34: - | AT34: 0 | AU34: - | AV34: 249 | AW34: - | AX34: 50 | AY34: - | AZ34: 0.20080321 | BA34: - | BC34: - | BH34: 1 | BI34: D | BJ34: 41 | BK34: 2013 | BL34: - | BM34: F | BN34: 216 | BO34: 613 | BP34: -
A35: 45138 | B35: 限时 | C35: 无 | F35: 42.2 | H35: =IFERROR(E35/G35-1,"") | I35: 39 | J35: =IFERROR(E35/I35,"") | K35: =IFERROR(E35/#REF!,"") | L35: 119465 | M35: - | R35: 29531 | S35: 0 | W35: - | Y35: - | AA35: - | AC35: - | AD35: 36 | AE35: - | AG35: - | AH35: 3981 | AI35: - | AJ35: 896 | AK35: - | AL35: 136 | AM35: - | AN35: 5178 | AO35: - | AP35: 2214 | AQ35: - | AR35: 326 | AS35: - | AT35: 0.0136 | AU35: - | BH35: 1 | BI35: D | BJ35: 34 | BK35: 2235 | BL35: - | BM35: F | BN35: 199 | BO35: 628 | BP35: -
A36: 45139 | B36: S级 | C36: 无 | F36: =E36-3.2 -> #VALUE! | I36: 19 | J36: =IFERROR(E36/I36,"") | K36: =IFERROR(E36/#REF!,"") | L36: 151183 | M36: - | O36: 13.186 | W36: - | Y36: - | AA36: - | AC36: - | AD36: 29 | AE36: - | AG36: - | AH36: 4932 | AI36: - | AJ36: 1019 | AK36: - | AL36: 131 | AM36: - | AN36: 4083 | AO36: - | AP36: 1983 | AQ36: - | AR36: 255 | AS36: - | AT36: 0.0083 | AV36: 225 | AW36: - | AX36: 0.0277 | AY36: - | BH36: 1 | BI36: D | BJ36: 32 | BK36: 2052 | BL36: - | BM36: F | BN36: 199 | BO36: 635 | BP36: - | BV36: 16GD32 | BW36: 13GD31 | BX36: 16QC05 | BY36: 16QD31 | BZ36: 海尔锦绣 | CA36: 16QD06W | CB36: 海尔云程 | CC36: 能率16E4 | CD36: 13GD32 | CE36: 13QD06W
A37: 45140 | B37: A级 | C37: 无 | F37: =E37-1.9 -> #VALUE! | I37: 12 | J37: =IFERROR(E37/I37,"") | K37: =IFERROR(E37/#REF!,"") | L37: 71181 | M37: - | W37: - | Y37: - | AA37: - | AC37: - | AD37: 33 | AE37: - | AG37: - | AH37: 5083 | AI37: - | AJ37: 801 | AK37: - | AL37: 106 | AM37: - | AN37: 3595 | AO37: - | AP37: 2166 | AQ37: - | AR37: 315 | AS37: - | BH37: 1 | BI37: C | BJ37: 19 | BK37: 3083 | BL37: - | BM37: F | BN37: 128 | BO37: 935 | BP37: -
A38: 45141 | B38: A级 | C38: 无 | F38: =E38-1.9 -> #VALUE! | I38: 10 | J38: =IFERROR(E38/I38,"") | K38: =IFERROR(E38/#REF!,"") | L38: 54265 | M38: - | W38: - | Y38: - | AA38: - | AC38: - | AD38: 32 | AE38: - | AG38: - | AH38: 4786 | AI38: - | AJ38: 193 | AK38: - | AL38: 129 | AM38: - | AN38: 2773 | AO38: - | AP38: 2047 | AQ38: - | AR38: 248 | AS38: - | BH38: 1 | BI38: D | BJ38: 35 | BK38: 2041 | BL38: - | BM38: F | BN38: 177 | BO38: 710 | BP38: -
A39: 45142 | B39: A级 | C39: 无 | F39: =E39-1.9 -> #VALUE! | I39: 13 | J39: =IFERROR(E39/I39,"") | K39: =IFERROR(E39/#REF!,"") | L39: 51135 | M39: - | W39: - | Y39: - | AA39: - | AC39: - | AD39: 37 | AE39: - | AG39: - | AH39: 5264 | AI39: - | AJ39: 475 | AK39: - | AL39: 113 | AM39: - | AN39: 6855 | AO39: - | AP39: 2351 | AQ39: - | AR39: 276 | AS39: - | BH39: 0.95 | BI39: D | BJ39: 31 | BK39: 2193 | BL39: - | BM39: F | BN39: 199 | BO39: 642 | BP39: -
A40: 45143 | B40: 预售 | C40: 无 | F40: =E40 | I40: 0 | J40: =IFERROR(E40/I40,"") | K40: =IFERROR(E40/#REF!,"") | L40: 19694 | M40: - | W40: - | Y40: - | AA40: - | AC40: - | AD40: 26 | AE40: - | AG40: - | AH40: 5661 | AI40: - | AJ40: 913 | AK40: - | AL40: 148 | AM40: - | AN40: 1388 | AO40: - | AP40: 2427 | AQ40: - | AR40: 374 | AS40: - | BH40: 0.95 | BI40: D | BJ40: 26 | BK40: 2440 | BL40: - | BM40: F | BN40: 171 | BO40: 760 | BP40: -
...

Sheet 单品16GD32
A1: 100039706989 | D1: 销售出库 | V1: 流量 | AT1: 转化 | BH1: 京仓现货率 | BI1: 关键词排名 | BQ1: 流失分析 | CF1: 负同比每日分析
A2: 日期 | B2: 价格政策 | D2: 销售额 | L2: 模块销售占比 | V2: PV | X2: UV | Z2: 人均浏览量 | AB2: 平均停留时间 | AD2: 关注人数 | AF2: 加购人数 | AH2: 站内免费 | AJ2: 站内付费 | AL2: 站外免费 | AN2: 站外付费 | AP2: 搜索 | AR2: 内容 | AT2: 店铺转化率 | AV2: 询单 数 | AX2: 询单 率 | AZ2: 询单 成交数 | BB2: 询单 转化 | BD2: 静默成交数 | BF2: 静默转化 | BI2: 燃气热水器 | BM2: 热水器 | BQ2: 流量流失 | BV2: 销售流失
B3: Y-23 | C3: Y-22 | D3: Y-23 数量 | E3: Y-23 金额 | F3: 实际销售 | G3: Y-22 金额 | H3: 同比 | I3: 目标 | J3: 达成率 | K3: 类目占比 | L3: 推广成交金额 | M3: 同比 | N3: 占比 | O3: 客服成交金额 | P3: 同比 | Q3: 占比 | R3: Y-23 | S3: Y-22 | T3: 同比 | U3: 占比 | V3: Y-23 | W3: Y-22 | X3: Y-23 | Y3: Y-22 | Z3: Y-23 | AA3: Y-22 | AB3: Y-23 | AC3: Y-22 | AD3: Y-23 | AE3: Y-22 | AF3: Y-23 | AG3: Y-22 | AH3: Y-23 | AI3: Y-22 | AJ3: Y-23 | AK3: Y-22 | AL3: Y-23 | AM3: Y-22 | AN3: Y-23 | AO3: Y-22 | AP3: Y-23 | AQ3: Y-22 | AR3: Y-23 | AS3: Y-22 | AT3: Y-23 | AU3: Y-22 | AV3: Y-23 | AW3: Y-22 | AX3: Y-23 | AY3: Y-22 | AZ3: Y-23 | BA3: Y-22 | BB3: Y-23 | BC3: Y-22 | BD3: Y-23 | BE3: Y-22 | BF3: Y-23 | BG3: Y-22 | BI3: 层级 | BJ3: 排名 | BK3: 搜索曝光 | BL3: Y-22搜索曝光 | BM3: 层级 | BN3: 排名 | BO3: 搜索曝光 | BP3: Y-22搜索曝光 | BQ3: TOP 1 | BR3: TOP 2 | BS3: TOP 3 | BT3: TOP 4 | BU3: TOP 5 | BV3: TOP 1 | BW3: TOP 2 | BX3: TOP 3 | BY3: TOP 4 | BZ3: TOP 5 | CA3: TOP 6 | CB3: TOP 7 | CC3: TOP 8 | CD3: TOP 9 | CE3: TOP 10
A4: 填写人员 | B4: 运营 | C4: 运营 | D4: 张超 | E4: 张超 | F4: 运营 | G4: 张超 | H4: 张超 | I4: 张超 | J4: 张超 | K4: 张超 | L4: 推广 | M4: 推广 | N4: 推广 | O4: 客服 | P4: 客服 | Q4: 客服 | R4: 直播 | S4: 直播 | T4: 直播 | U4: 直播 | V4: 运营 | W4: 运营 | X4: 运营 | Y4: 运营 | Z4: 运营 | AA4: 运营 | AB4: 运营 | AC4: 运营 | AD4: 运营 | AE4: 运营 | AF4: 运营 | AG4: 运营 | AH4: 运营 | AI4: 运营 | AJ4: 运营 | AK4: 运营 | AL4: 运营 | AM4: 运营 | AN4: 运营 | AO4: 运营 | AP4: 运营 | AQ4: 运营 | AR4: 运营 | AS4: 运营 | AT4: 客服 | AU4: 客服 | AV4: 客服 | AW4: 客服 | AX4: 客服 | AY4: 客服 | AZ4: 客服 | BA4: 客服 | BB4: 客服 | BC4: 客服 | BD4: 客服 | BE4: 客服 | BF4: 客服 | BG4: 客服 | BH4: 供应链 | BI4: 运营 | BJ4: 运营 | BK4: 运营 | BL4: 运营 | BM4: 运营 | BN4: 运营 | BO4: 运营 | BP4: 运营 | BQ4: 运营 | BR4: 运营 | BS4: 运营 | BT4: 运营 | BU4: 运营 | BV4: 运营 | BW4: 运营 | BX4: 运营 | BY4: 运营 | BZ4: 运营 | CA4: 运营 | CB4: 运营 | CC4: 运营 | CD4: 运营 | CE4: 运营 | CF4: 运营
A5: 45108 | B5: A | C5: 无 | F5: 2.1294 | H5: =IFERROR(E5/G5-1,"") | I5: 1.0797 | J5: =IFERROR(E5/I5,"") | K5: =IFERROR(E5/#REF!,"") | L5: 31440 | M5: - | R5: 0 | S5: 0 | W5: - | Y5: - | AA5: - | AC5: - | AD5: 7 | AE5: - | AG5: - | AH5: 767 | AI5: - | AJ5: 274 | AK5: - | AL5: 20 | AM5: - | AN5: 18 | AO5: - | AP5: 300 | AQ5: - | AR5: 36 | AS5: - | AT5: 0.0031 | AU5: - | BI5: F | BJ5: 227 | BK5: 288 | BL5: - | BM5: F | BN5: 767 | BO5: 131 | BP5: -
A6: 45109 | B6: A | C6: 无 | F6: 1.7695 | H6: =IFERROR(E6/G6-1,"") | I6: 0.7198 | J6: =IFERROR(E6/I6,"") | K6: =IFERROR(E6/#REF!,"") | L6: 29514 | M6: - | R6: 0 | S6: 0 | W6: - | Y6: - | AA6: - | AC6: - | AD6: 8 | AE6: - | AG6: - | AH6: 853 | AI6: - | AJ6: 297 | AK6: - | AL6: 26 | AM6: - | AN6: 21 | AO6: - | AP6: 319 | AQ6: - | AR6: 49 | AS6: - | AT6: 0.0019 | AU6: - | BI6: F | BJ6: 142 | BK6: 455 | BL6: - | BM6: F | BN6: 1346 | BO6: 57 | BP6: -
A7: 45110 | B7: 预约 | C7: 无 | F7: 1.0497 | H7: =IFERROR(E7/G7-1,"") | I7: 0 | J7: =IFERROR(E7/I7,"") | K7: =IFERROR(E7/#REF!,"") | L7: 7098 | M7: - | R7: 0 | S7: 0 | W7: - | Y7: - | AA7: - | AC7: - | AD7: 12 | AE7: - | AG7: - | AH7: 991 | AI7: - | AJ7: 385 | AK7: - | AL7: 36 | AM7: - | AN7: 19 | AO7: - | AP7: 404 | AQ7: - | AR7: 61 | AS7: - | AT7: 0 | AU7: - | BI7: F | BJ7: 127 | BK7: 502 | BL7: - | BM7: F | BN7: 911 | BO7: 93 | BP7: - | BV7: 16GD31 | BW7: 16QD31 | BX7: 16QD06W | BY7: POP16GD32 | BZ7: 13GD31 | CA7: 16QC05 | CB7: 海尔云程 | CC7: 史密斯TJ1 | CD7: 厂直16GD32 | CE7: 海尔锦绣
A8: 45111 | B8: A | C8: 无 | F8: 6.8281 | H8: =IFERROR(E8/G8-1,"") | I8: 6.4782 | J8: =IFERROR(E8/I8,"") | K8: =IFERROR(E8/#REF!,"") | L8: 28992 | M8: - | R8: 0 | S8: 0 | W8: - | Y8: - | AA8: - | AC8: - | AD8: 12 | AE8: - | AG8: - | AH8: 1067 | AI8: - | AJ8: 331 | AK8: - | AL8: 45 | AM8: - | AN8: 31 | AO8: - | AP8: 440 | AQ8: - | AR8: 78 | AS8: - | AT8: 0.0137 | AU8: - | BI8: F | BJ8: 112 | BK8: 579 | BL8: - | BM8: F | BN8: 722 | BO8: 134 | BP8: -
A9: 45112 | B9: A | C9: 无 | F9: 7.5579 | H9: =IFERROR(E9/G9-1,"") | I9: 7.5579 | J9: =IFERROR(E9/I9,"") | K9: =IFERROR(E9/#REF!,"") | L9: 28452 | M9: - | R9: 3199 | S9: 0 | W9: - | Y9: - | AA9: - | AC9: - | AD9: 8 | AE9: - | AG9: - | AH9: 1234 | AI9: - | AJ9: 343 | AK9: - | AL9: 51 | AM9: - | AN9: 17 | AO9: - | AP9: 556 | AQ9: - | AR9: 73 | AS9: - | AT9: 0.0142 | AU9: - | BH9: 0.75 | BI9: E | BJ9: 75 | BK9: 826 | BL9: - | BM9: F | BN9: 526 | BO9: 191 | BP9: -
A10: 45113 | B10: 预约 | C10: 无 | F10: 0.6998 | H10: =IFERROR(E10/G10-1,"") | I10: 0 | J10: =IFERROR(E10/I10,"") | K10: =IFERROR(E10/#REF!,"") | L10: 9198 | M10: - | R10: 0 | S10: 0 | W10: - | Y10: - | AA10: - | AC10: - | AD10: 9 | AE10: - | AG10: - | AH10: 798 | AI10: - | AJ10: 297 | AK10: - | AL10: 55 | AM10: - | AN10: 11 | AO10: - | AP10: 259 | AQ10: - | AR10: 43 | AS10: - | AT10: 0 | AU10: - | BH10: 0.65 | BI10: F | BJ10: 199 | BK10: 295 | BL10: - | BM10: F | BN10: 970 | BO10: 78 | BP10: -
A11: 45114 | B11: A | C11: 无 | F11: 2.4893 | H11: =IFERROR(E11/G11-1,"") | I11: 1.4396 | J11: =IFERROR(E11/I11,"") | K11: =IFERROR(E11/#REF!,"") | L11: 9597 | M11: - | R11: 0 | S11: 0 | W11: - | Y11: - | AA11: - | AC11: - | AD11: 2 | AE11: - | AG11: - | AH11: 728 | AI11: - | AJ11: 147 | AK11: - | AL11: 25 | AM11: - | AN11: 11 | AO11: - | AP11: 222 | AQ11: - | AR11: 30 | AS11: - | AT11: 0.0048 | AU11: - | BH11: 0.45 | BI11: F | BJ11: 215 | BK11: 266 | BL11: - | BM11: F | BN11: 1086 | BO11: 65 | BP11: -
A12: 45115 | B12: A | C12: 无 | F12: 4.2888 | H12: =IFERROR(E12/G12-1,"") | I12: 3.2391 | J12: =IFERROR(E12/I12,"") | K12: =IFERROR(E12/#REF!,"") | L12: 7098 | M12: - | R12: 0 | S12: 0 | W12: - | Y12: - | AA12: - | AC12: - | AD12: 9 | AE12: - | AG12: - | AH12: 798 | AI12: - | AJ12: 215 | AK12: - | AL12: 36 | AM12: - | AN12: 7 | AO12: - | AP12: 290 | AQ12: - | AR12: 39 | AS12: - | AT12: 0.0093 | AU12: - | BI12: F | BJ12: 158 | BK12: 407 | BL12: - | BM12: F | BN12: 1054 | BO12: 80 | BP12: -
A13: 45116 | B13: 预约 | C13: 无 | F13: 1.0497 | H13: =IFERROR(E13/G13-1,"") | I13: 0 | J13: =IFERROR(E13/I13,"") | K13: =IFERROR(E13/#REF!,"") | L13: 2849 | M13: - | R13: 0 | S13: 0 | W13: - | Y13: - | AA13: - | AC13: - | AD13: 4 | AE13: - | AG13: - | AH13: 895 | AI13: - | AJ13: 355 | AK13: - | AL13: 25 | AM13: - | AN13: 19 | AO13: - | AP13: 336 | AQ13: - | AR13: 61 | AS13: - | AT13: 0 | AU13: - | BI13: F | BJ13: 200 | BK13: 352 | BL13: - | BM13: F | BN13: 1451 | BO13: 50 | BP13: -
A14: 45117 | B14: 预约 | C14: 无 | F14: 1.0497 | H14: =IFERROR(E14/G14-1,"") | I14: 0 | J14: =IFERROR(E14/I14,"") | K14: =IFERROR(E14/#REF!,"") | L14: 9720 | M14: - | R14: 0 | S14: 0 | W14: - | Y14: - | AA14: - | AC14: - | AD14: 5 | AE14: - | AG14: - | AH14: 826 | AI14: - | AJ14: 281 | AK14: - | AL14: 25 | AM14: - | AN14: 17 | AO14: - | AP14: 251 | AQ14: - | AR14: 45 | AS14: - | AT14: 0 | AU14: - | BH14: 0.65 | BI14: F | BJ14: 221 | BK14: 288 | BL14: - | BM14: F | BN14: 1246 | BO14: 56 | BP14: -
A15: 45118 | B15: A | C15: 无 | F15: 7.9381 | H15: =IFERROR(E15/G15-1,"") | I15: 7.9381 | J15: =IFERROR(E15/I15,"") | K15: =IFERROR(E15/#REF!,"") | L15: 23893 | M15: - | R15: 6398 | S15: 0 | W15: - | Y15: - | AA15: - | AC15: - | AD15: 4 | AE15: - | AG15: - | AH15: 731 | AI15: - | AJ15: 262 | AK15: - | AL15: 23 | AM15: - | AN15: 44 | AO15: - | AP15: 214 | AQ15: - | AR15: 59 | AS15: - | AT15: 0.0122 | AU15: - | BI15: F | BJ15: 334 | BK15: 192 | BL15: - | BM15: F | BN15: 1071 | BO15: 76 | BP15: - | BV15: 16QD31 | BW15: 16GD31 | BX15: 16QD06W | BY15: 厂直16GD32 | BZ15: 16QC05 | CA15: POP16GD32 | CB15: 13QC05 | CC15: 海尔锦绣 | CD15: POP16QC06 | CE15: 海尔云程
A16: 45119 | B16: A | C16: 无 | F16: 4.1489 | H16: =IFERROR(E16/G16-1,"") | I16: 8.8 | J16: =IFERROR(E16/I16,"") | K16: =IFERROR(E16/#REF!,"") | L16: 14095 | M16: - | R16: 0 | S16: 0 | W16: - | Y16: - | AA16: - | AC16: - | AD16: 5 | AE16: - | AG16: - | AH16: 730 | AI16: - | AJ16: 132 | AK16: - | AL16: 24 | AM16: - | AN16: 24 | AO16: - | AP16: 235 | AQ16: - | AR16: 57 | AS16: - | AT16: 0.0095 | AU16: - | BH16: 0.8 | BI16: F | BJ16: 275 | BK16: 239 | BL16: - | BM16: F | BN16: 958 | BO16: 90 | BP16: -
A17: 45120 | B17: A | C17: 无 | F17: 4.6087 | H17: =IFERROR(E17/G17-1,"") | I17: 7.2 | J17: =IFERROR(E17/I17,"") | K17: =IFERROR(E17/#REF!,"") | L17: 14196 | M17: - | R17: 3199 | S17: 0 | W17: - | Y17: - | AA17: - | AC17: - | AD17: 1 | AE17: - | AG17: - | AH17: 709 | AI17: - | AJ17: 262 | AK17: - | AL17: 50 | AM17: - | AN17: 32 | AO17: - | AP17: 236 | AQ17: - | AR17: 37 | AS17: - | AT17: 0.0065 | AU17: - | BH17: 0.8 | BI17: F | BJ17: 378 | BK17: 161 | BL17: - | BM17: F | BN17: 1323 | BO17: 51 | BP17: -
A18: 45121 | B18: 预约 | C18: 无 | F18: 3.9389 | H18: =IFERROR(E18/G18-1,"") | I18: 0 | J18: =IFERROR(E18/I18,"") | K18: =IFERROR(E18/#REF!,"") | L18: 19476 | M18: - | R18: ？ | S18: 0 | W18: - | Y18: - | AA18: - | AC18: - | AD18: 5 | AE18: - | AG18: - | AH18: 938 | AI18: - | AJ18: 302 | AK18: - | AL18: 27 | AM18: - | AN18: 92 | AO18: - | AP18: 389 | AQ18: - | AR18: 104 | AS18: - | AT18: 0.0074 | AU18: - | BH18: 0.85 | BI18: F | BJ18: 189 | BK18: 364 | BL18: - | BM18: F | BN18: 653 | BO18: 165 | BP18: -
A19: 45122 | B19: 预约 | C19: 无 | F19: 1.0497 | H19: =IFERROR(E19/G19-1,"") | I19: 0 | J19: =IFERROR(E19/I19,"") | K19: =IFERROR(E19/#REF!,"") | L19: 19576 | M19: - | R19: 0 | S19: 0 | W19: - | Y19: - | AA19: - | AC19: - | AD19: 7 | AE19: - | AG19: - | AH19: 1049 | AI19: - | AJ19: 484 | AK19: - | AL19: 27 | AM19: - | AN19: 51 | AO19: - | AP19: 466 | AQ19: - | AR19: 91 | AS19: - | AT19: 0 | AU19: - | BI19: F | BJ19: 130 | BK19: 505 | BL19: - | BM19: F | BN19: 787 | BO19: 130 | BP19: -
A20: 45123 | B20: S | C20: 无 | F20: 3.9189 | H20: =IFERROR(E20/G20-1,"") | I20: 22.4 | J20: =IFERROR(E20/I20,"") | K20: =IFERROR(E20/#REF!,"") | L20: 34790 | M20: - | R20: 6798 | S20: 0 | W20: - | Y20: - | AA20: - | AC20: - | AD20: 8 | AE20: - | AG20: - | AH20: 1340 | AI20: - | AJ20: 635 | AK20: - | AL20: 37 | AM20: - | AN20: 66 | AO20: - | AP20: 614 | AQ20: - | AR20: 137 | AS20: - | AT20: 0.0038 | AU20: - | BI20: F | BJ20: 147 | BK20: 518 | BL20: - | BM20: F | BN20: 1104 | BO20: 132 | BP20: -
A21: 45124 | B21: S | C21: 无 | F21: 6.4382 | H21: =IFERROR(E21/G21-1,"") | I21: 14.4 | J21: =IFERROR(E21/I21,"") | K21: =IFERROR(E21/#REF!,"") | L21: 47484 | M21: - | R21: 3199 | S21: 0 | W21: - | Y21: - | AA21: - | AC21: - | AD21: 13 | AE21: - | AG21: - | AH21: 1490 | AI21: - | AJ21: 509 | AK21: - | AL21: 40 | AM21: - | AN21: 16 | AO21: - | AP21: 717 | AQ21: - | AR21: 140 | AS21: - | AT21: 0.0078 | AU21: - | BH21: 0.85 | BI21: E | BJ21: 89 | BK21: 703 | BL21: - | BM21: F | BN21: 875 | BO21: 170 | BP21: -
A22: 45125 | B22: A | C22: 无 | F22: 5.6884 | H22: =IFERROR(E22/G22-1,"") | I22: 7.2 | J22: =IFERROR(E22/I22,"") | K22: =IFERROR(E22/#REF!,"") | L22: 70130 | M22: - | R22: 6398 | S22: 0 | W22: - | Y22: - | AA22: - | AC22: - | AD22: 11 | AE22: - | AG22: - | AH22: 1223 | AI22: - | AJ22: 372 | AK22: - | AL22: 35 | AM22: - | AN22: 23 | AO22: - | AP22: 606 | AQ22: - | AR22: 129 | AS22: - | AT22: 0.0061 | AU22: - | BH22: 0.85 | BI22: F | BJ22: 121 | BK22: 512 | BL22: - | BM22: F | BN22: 913 | BO22: 123 | BP22: - | BV22: 16GD31 | BW22: 16QD31 | BX22: 16QD06W | BY22: 13GD32 | BZ22: 16QD06* | CA22: 16QC05 | CB22: 厂直16GD32 | CC22: POP16GD32 | CD22: 海尔锦绣 | CE22: POP16QC06
A23: 45126 | B23: 预售 | C23: 无 | F23: 2.1494 | H23: =IFERROR(E23/G23-1,"") | I23: 0 | J23: =IFERROR(E23/I23,"") | K23: =IFERROR(E23/#REF!,"") | L23: 44581 | M23: - | R23: 0 | S23: 0 | W23: - | Y23: - | AA23: - | AC23: - | AD23: 5 | AE23: - | AG23: - | AH23: 1141 | AI23: - | AJ23: 337 | AK23: - | AL23: 27 | AM23: - | AN23: 22 | AO23: - | AP23: 540 | AQ23: - | AR23: 130 | AS23: - | AT23: 0.0037 | AU23: - | BH23: 0.85 | BI23: F | BJ23: 158 | BK23: 428 | BL23: - | BM23: F | BN23: 1195 | BO23: 91 | BP23: -
A24: 45127 | B24: 预售 | C24: 无 | F24: 5.351 | H24: =IFERROR(E24/G24-1,"") | I24: 13.6 | J24: =IFERROR(E24/I24,"") | K24: =IFERROR(E24/#REF!,"") | L24: 19715 | M24: - | R24: 3199 | S24: 0 | W24: - | Y24: - | AA24: - | AC24: - | AD24: 9 | AE24: - | AG24: - | AH24: 1038 | AI24: - | AJ24: 322 | AK24: - | AL24: 28 | AM24: - | AN24: 18 | AO24: - | AP24: 492 | AQ24: - | AR24: 117 | AS24: - | AT24: 0.0098 | AU24: - | BH24: 0.65 | BI24: F | BJ24: 166 | BK24: 391 | BL24: - | BM24: F | BN24: 848 | BO24: 114 | BP24: -
A25: 45128 | B25: S | C25: 无 | F25: 5.0011 | H25: =IFERROR(E25/G25-1,"") | I25: 10.4 | J25: =IFERROR(E25/I25,"") | K25: =IFERROR(E25/#REF!,"") | L25: 20494 | M25: - | R25: 0 | S25: 0 | W25: - | Y25: - | AA25: - | AC25: - | AD25: 8 | AE25: - | AG25: - | AH25: 1275 | AI25: - | AJ25: 312 | AK25: - | AL25: 48 | AM25: - | AN25: 770 | AO25: - | AP25: 652 | AQ25: - | AR25: 125 | AS25: - | AT25: 0.0054 | AU25: - | BH25: 0.55 | BI25: E | BJ25: 94 | BK25: 623 | BL25: - | BM25: F | BN25: 540 | BO25: 195 | BP25: -
A26: 45129 | B26: A | C26: 无 | F26: 6.7481 | H26: =IFERROR(E26/G26-1,"") | I26: 7.2 | J26: =IFERROR(E26/I26,"") | K26: =IFERROR(E26/#REF!,"") | L26: 17395 | M26: - | R26: 6246 | S26: 0 | W26: - | Y26: - | AA26: - | AC26: - | AD26: 11 | AE26: - | AG26: - | AH26: 1692 | AI26: - | AJ26: 399 | AK26: - | AL26: 39 | AM26: - | AN26: 2849 | AO26: - | AP26: 871 | AQ26: - | AR26: 155 | AS26: - | AT26: 0.0036 | AU26: - | BI26: E | BJ26: 73 | BK26: 946 | BL26: - | BM26: F | BN26: 481 | BO26: 251 | BP26: -
A27: 45130 | B27: A | C27: 无 | F27: 5.7015 | H27: =IFERROR(E27/G27-1,"") | I27: 0 | J27: =IFERROR(E27/I27,"") | K27: =IFERROR(E27/#REF!,"") | L27: 55266 | M27: - | R27: 0 | S27: 0 | W27: - | Y27: - | AA27: - | AC27: - | AD27: 16 | AE27: - | AG27: - | AH27: 1977 | AI27: - | AJ27: 521 | AK27: - | AL27: 51 | AM27: - | AN27: 1953 | AO27: - | AP27: 1151 | AQ27: - | AR27: 194 | AS27: - | AT27: 0.0029 | AU27: - | BI27: E | BJ27: 65 | BK27: 1180 | BL27: - | BM27: F | BN27: 426 | BO27: 295 | BP27: -
A28: 45131 | B28: 预约 | C28: 无 | F28: 5.0389 | H28: =IFERROR(E28/G28-1,"") | I28: 14.4 | J28: =IFERROR(E28/I28,"") | K28: =IFERROR(E28/#REF!,"") | L28: 35979 | M28: - | R28: 9597 | S28: 0 | W28: - | Y28: - | AA28: - | AC28: - | AD28: 12 | AE28: - | AG28: - | AH28: 1657 | AI28: - | AJ28: 596 | AK28: - | AL28: 49 | AM28: - | AN28: 2800 | AO28: - | AP28: 800 | AQ28: - | AR28: 161 | AS28: - | AT28: 0.003 | AU28: - | BH28: 0.8 | BI28: E | BJ28: 77 | BK28: 830 | BL28: - | BM28: F | BN28: 579 | BO28: 184 | BP28: -
A29: 45132 | B29: S | C29: 无 | F29: 10.4196 | H29: =IFERROR(E29/G29-1,"") | I29: 11.2 | J29: =IFERROR(E29/I29,"") | K29: =IFERROR(E29/#REF!,"") | L29: 28673 | M29: - | R29: 3199 | S29: 0 | W29: - | Y29: - | AA29: - | AC29: - | AD29: 6 | AE29: - | AG29: - | AH29: 1825 | AI29: - | AJ29: 470 | AK29: - | AL29: 75 | AM29: - | AN29: 1091 | AO29: - | AP29: 971 | AQ29: - | AR29: 144 | AS29: - | AT29: 0.0092 | AU29: - | BH29: 0.95 | BI29: E | BJ29: 65 | BK29: 1041 | BL29: - | BM29: F | BN29: 393 | BO29: 288 | BP29: - | BV29: 16QD31 | BW29: 16GD31 | BX29: 厂直16GD32 | BY29: 13GD31 | BZ29: 厂直16GD31 | CA29: 16QD06W | CB29: 厂直13GD31 | CC29: 13GD32 | CD29: 16QC05 | CE29: 五星16GD32
A30: 45133 | B30: A | C30: 无 | F30: 22.854 | H30: =IFERROR(E30/G30-1,"") | I30: 6.4 | J30: =IFERROR(E30/I30,"") | K30: =IFERROR(E30/#REF!,"") | L30: 18725 | M30: - | R30: 0 | S30: 0 | W30: - | Y30: - | AA30: - | AC30: - | AD30: 19 | AE30: - | AG30: - | AH30: 1759 | AI30: - | AJ30: 364 | AK30: - | AL30: 69 | AM30: - | AN30: 732 | AO30: - | AP30: 942 | AQ30: - | AR30: 164 | AS30: - | AT30: 0.0123 | AU30: - | BI30: E | BJ30: 59 | BK30: 1091 | BL30: - | BM30: F | BN30: 376 | BO30: 305 | BP30: -
A31: 45134 | B31: A | C31: 无 | F31: 18.9403 | H31: =IFERROR(E31/G31-1,"") | I31: 8 | J31: =IFERROR(E31/I31,"") | K31: =IFERROR(E31/#REF!,"") | L31: 15977 | M31: - | R31: 3199 | S31: 0 | W31: - | Y31: - | AA31: - | AC31: - | AD31: 19 | AE31: - | AG31: - | AH31: 1863 | AI31: - | AJ31: 429 | AK31: - | AL31: 64 | AM31: - | AN31: 1198 | AO31: - | AP31: 1006 | AQ31: - | AR31: 187 | AS31: - | AT31: 0.0098 | AU31: - | BH31: 0.95 | BI31: E | BJ31: 63 | BK31: 984 | BL31: - | BM31: F | BN31: 363 | BO31: 309 | BP31: -
A32: 45135 | B32: A | C32: 无 | F32: 6.8031 | H32: =IFERROR(E32/G32-1,"") | I32: 8 | J32: =IFERROR(E32/I32,"") | K32: =IFERROR(E32/#REF!,"") | L32: 18535 | M32: - | R32: 0 | S32: 0 | W32: - | Y32: - | AA32: - | AC32: - | AD32: 11 | AE32: - | AG32: - | AH32: 1770 | AI32: - | AJ32: 317 | AK32: - | AL32: 34 | AM32: - | AN32: 2051 | AO32: - | AP32: 940 | AQ32: - | AR32: 158 | AS32: - | AT32: 0.0049 | AU32: - | BH32: 0.9 | BI32: E | BJ32: 57 | BK32: 1055 | BL32: - | BM32: F | BN32: 361 | BO32: 296 | BP32: -
A33: 45136 | B33: 预售 | C33: 无 | F33: 0.3499 | H33: =IFERROR(E33/G33-1,"") | I33: 0 | J33: =IFERROR(E33/I33,"") | K33: =IFERROR(E33/#REF!,"") | L33: 21194 | M33: - | R33: 0 | S33: 0 | W33: - | Y33: - | AA33: - | AC33: - | AD33: 21 | AE33: - | AG33: - | AH33: 2199 | AI33: - | AJ33: 497 | AK33: - | AL33: 76 | AM33: - | AN33: 4368 | AO33: - | AP33: 1194 | AQ33: - | AR33: 160 | AS33: - | AT33: 0 | AU33: - | BI33: E | BJ33: 52 | BK33: 1205 | BL33: - | BM33: F | BN33: 338 | BO33: 367 | BP33: -
A34: 45137 | B34: 预售 | C34: 无 | F34: =E34 | H34: =IFERROR(E34/G34-1,"") | I34: 0 | J34: =IFERROR(E34/I34,"") | K34: =IFERROR(E34/#REF!,"") | L34: 23453 | M34: - | O34: 14.7459 | P34: / | Q34: 0.1344 | R34: 0 | S34: 0 | W34: - | Y34: - | AA34: - | AC34: - | AD34: 11 | AE34: - | AG34: - | AH34: 2092 | AI34: - | AJ34: 449 | AK34: - | AL34: 53 | AM34: - | AN34: 1815 | AO34: - | AP34: 1105 | AQ34: - | AR34: 130 | AS34: - | AT34: 0 | AU34: - | AV34: 115 | AW34: - | AY34: - | AZ34: 15 | BA34: - | BB34: 0.13043478 | BC34: - | BH34: 0.8 | BI34: E | BJ34: 58 | BK34: 1231 | BL34: - | BM34: F | BN34: 357 | BO34: 342 | BP34: -
